<?xml version="1.0" encoding="utf-8"?>
<!-- This URDF was automatically created by SolidWorks to URDF Exporter! Originally created by Stephen Brawner (brawner@gmail.com) 
     Commit Version: 1.6.0-4-g7f85cfe  Build Version: 1.6.7995.38578
     For more information, please see http://wiki.ros.org/sw_urdf_exporter -->
<robot name="REV" xmlns:xacro="http://wiki.ros.org/xacro">
  <xacro:macro name="rover_module" params="parent_link tf_prefix='' right_upper_suspension_x='' left_upper_suspension_x='' right_elbow_multiplier='' 
  right_lower_suspension_multiplier='' left_elbow_multiplier='' left_lower_suspension_multiplier=''" >
    <link
      name="${tf_prefix}_base_link">
      <inertial>
        <origin
          xyz="-1.00613961606655E-15 1.15012166457262E-15 0.133292991245626"
          rpy="0 0 0" />
        <mass
          value="1.16420090238786" />
        <inertia
          ixx="0.0164887637751647"
          ixy="-3.2977140848238E-17"
          ixz="5.13285653272394E-17"
          iyy="0.00758057045639268"
          iyz="3.48874342128307E-18"
          izz="0.00955960807272672" />
      </inertial>
      <visual>
        <origin
          xyz="0 0 0"
          rpy="0 0 0" />
        <geometry>
          <mesh
            filename="package://rover_description/meshes/${tf_prefix}_base_link.STL" />
        </geometry>
        <material
          name="">
          <color
            rgba="0.898039215686275 0.917647058823529 0.929411764705882 1" />
        </material>
      </visual>
      <collision>
        <origin
          xyz="0 0 0"
          rpy="0 0 0" />
        <geometry>
          <mesh
            filename="package://rover_description/meshes/${tf_prefix}_base_link.STL" />
        </geometry>
      </collision>
    </link>
    <joint name="${tf_prefix}_base_joint" type="fixed">
        <parent link="${parent_link}"/>
        <child link="${tf_prefix}_base_link"/>
        <origin xyz="0 0 0" rpy="0 0 0"/>
    </joint>
    <link
      name="${tf_prefix}_right_upper_arm_link">
      <inertial>
        <origin
          xyz="-7.42461647718073E-16 -0.100934469042325 0.0100945068323446"
          rpy="0 0 0" />
        <mass
          value="0.0892451135572811" />
        <inertia
          ixx="0.000466766221391411"
          ixy="-8.41322564394238E-19"
          ixz="-8.12262460963765E-19"
          iyy="0.000121199401866971"
          iyz="-4.51700500372392E-05"
          izz="0.00052918842893447" />
      </inertial>
      <visual>
        <origin
          xyz="0 0 0"
          rpy="0 0 0" />
        <geometry>
          <mesh
            filename="package://rover_description/meshes/${tf_prefix}_right_upper_arm_link.STL" />
        </geometry>
        <material
          name="">
          <color
            rgba="1 0 0.501960784313725 1" />
        </material>
      </visual>
      <collision>
        <origin
          xyz="0 0 0"
          rpy="0 0 0" />
        <geometry>
          <mesh
            filename="package://rover_description/meshes/${tf_prefix}_right_upper_arm_link.STL" />
        </geometry>
      </collision>
    </link>
    <joint
      name="${tf_prefix}_right_upper_suspension_joint"
      type="continuous">
      <origin
        xyz="0 -0.113029999999999 0.200078600000003"
        rpy="0 0 0" />
      <parent
        link="${tf_prefix}_base_link" />
      <child
        link="${tf_prefix}_right_upper_arm_link" />
      <axis
        xyz="${right_upper_suspension_x} 0 0" />
    </joint>
    <link
      name="${tf_prefix}_right_elbow_link">
      <inertial>
        <origin
          xyz="1.73472347597681E-16 -0.0305089501910714 -0.0605771102539999"
          rpy="0 0 0" />
        <mass
          value="0.276177502867985" />
        <inertia
          ixx="0.00138370097439145"
          ixy="3.11337756540843E-18"
          ixz="1.06163039660916E-18"
          iyy="0.00118184162619848"
          iyz="-1.67240900157388E-05"
          izz="0.000604637115743066" />
      </inertial>
      <visual>
        <origin
          xyz="0 0 0"
          rpy="0 0 0" />
        <geometry>
          <mesh
            filename="package://rover_description/meshes/${tf_prefix}_right_elbow_link.STL" />
        </geometry>
        <material
          name="">
          <color
            rgba="0.898039215686275 0.917647058823529 0.929411764705882 1" />
        </material>
      </visual>
      <collision>
        <origin
          xyz="0 0 0"
          rpy="0 0 0" />
        <geometry>
          <mesh
            filename="package://rover_description/meshes/${tf_prefix}_right_elbow_link.STL" />
        </geometry>
      </collision>
    </link>
    <joint
      name="${tf_prefix}_right_elbow_joint"
      type="continuous">
      <origin
        xyz="0 -0.228276477206557 -0.0121577117157992"
        rpy="0 0 0" />
      <parent
        link="${tf_prefix}_right_upper_arm_link" />
      <child
        link="${tf_prefix}_right_elbow_link" />
      <axis
        xyz="-1 0 0" />
      <mimic
        joint="${tf_prefix}_right_upper_suspension_joint"
        multiplier="${right_elbow_multiplier}"
        offset="0" />
    </joint>
    <link
      name="${tf_prefix}_right_steer_link">
      <inertial>
        <origin
          xyz="-4.00224438692684E-05 -0.0556417904968233 -0.0380442093757095"
          rpy="0 0 0" />
        <mass
          value="0.491364303359802" />
        <inertia
          ixx="0.00176190750016323"
          ixy="-2.3086894763016E-08"
          ixz="-5.99035081975197E-07"
          iyy="0.0021935871105742"
          iyz="-0.000325354991132058"
          izz="0.00127549915002927" />
      </inertial>
      <visual>
        <origin
          xyz="0 0 0"
          rpy="0 0 0" />
        <geometry>
          <mesh
            filename="package://rover_description/meshes/${tf_prefix}_right_steer_link.STL" />
        </geometry>
        <material
          name="">
          <color
            rgba="0.792156862745098 0.819607843137255 0.933333333333333 1" />
        </material>
      </visual>
      <collision>
        <origin
          xyz="0 0 0"
          rpy="0 0 0" />
        <geometry>
          <mesh
            filename="package://rover_description/meshes/${tf_prefix}_right_steer_link.STL" />
        </geometry>
      </collision>
    </link>
    <joint
      name="${tf_prefix}_right_steer_joint"
      type="continuous">
      <origin
        xyz="0 -0.0763523999319007 -0.142621"
        rpy="0 0 0" />
      <parent
        link="${tf_prefix}_right_elbow_link" />
      <child
        link="${tf_prefix}_right_steer_link" />
      <axis
        xyz="0 0 1" />
    </joint>
    <link
      name="${tf_prefix}_right_drive_link">
      <inertial>
        <origin
          xyz="-9.1240169641793E-08 0.0485815654598082 -4.94940420933815E-05"
          rpy="0 0 0" />
        <mass
          value="0.38738629716804" />
        <inertia
          ixx="0.000796364048811921"
          ixy="-1.03091902147451E-18"
          ixz="2.51759367747659E-18"
          iyy="0.00098932746486517"
          iyz="3.40772342893294E-19"
          izz="0.000796364048811921" />
      </inertial>
      <visual>
        <origin
          xyz="0 0 0"
          rpy="0 0 0" />
        <geometry>
          <mesh
            filename="package://rover_description/meshes/${tf_prefix}_right_drive_link.STL" />
        </geometry>
        <material
          name="">
          <color
            rgba="0.792156862745098 0.819607843137255 0.933333333333333 1" />
        </material>
      </visual>
      <collision>
        <origin
          xyz="0 0 0"
          rpy="0 0 0" />
        <geometry>
          <mesh
            filename="package://rover_description/meshes/${tf_prefix}_right_drive_link.STL" />
        </geometry>
      </collision>
    </link>
    <joint
      name="${tf_prefix}_right_drive_joint"
      type="continuous">
      <origin
        xyz="0 -0.173278800694993 -0.0550676156179471"
        rpy="0 0 0" />
      <parent
        link="${tf_prefix}_right_steer_link" />
      <child
        link="${tf_prefix}_right_drive_link" />
      <axis
        xyz="0 -1 0" />
    </joint>
    <link
      name="${tf_prefix}_right_lower_arm_link">
      <inertial>
        <origin
          xyz="-9.92261828258734E-16 -0.0916467009361195 -0.00210488781760905"
          rpy="0 0 0" />
        <mass
          value="0.0901506877798632" />
        <inertia
          ixx="0.000709947389465218"
          ixy="-3.05892455674334E-18"
          ixz="-2.00090481948651E-20"
          iyy="8.29725926351233E-05"
          iyz="1.14681908319405E-05"
          izz="0.000732993105541909" />
      </inertial>
      <visual>
        <origin
          xyz="0 0 0"
          rpy="0 0 0" />
        <geometry>
          <mesh
            filename="package://rover_description/meshes/${tf_prefix}_right_lower_arm_link.STL" />
        </geometry>
        <material
          name="">
          <color
            rgba="0.341176470588235 0.83921568627451 0.411764705882353 1" />
        </material>
      </visual>
      <collision>
        <origin
          xyz="0 0 0"
          rpy="0 0 0" />
        <geometry>
          <mesh
            filename="package://rover_description/meshes/${tf_prefix}_right_lower_arm_link.STL" />
        </geometry>
      </collision>
    </link>
    <joint
      name="${tf_prefix}_right_lower_suspension_joint"
      type="continuous">
      <origin
        xyz="0 -0.0685799999999988 0.111178600000003"
        rpy="0 0 0" />
      <parent
        link="${tf_prefix}_base_link" />
      <child
        link="${tf_prefix}_right_lower_arm_link" />
      <axis
        xyz="-1 0 0" />
      <mimic
        joint="${tf_prefix}_right_upper_suspension_joint"
        multiplier="${right_lower_suspension_multiplier}"
        offset="0" />
    </joint>
    <link
      name="${tf_prefix}_left_upper_arm_link">
      <inertial>
        <origin
          xyz="-2.70616862252382E-16 0.0988816966262285 0.0226291003215506"
          rpy="0 0 0" />
        <mass
          value="0.0892451135572811" />
        <inertia
          ixx="0.000466766221391411"
          ixy="-8.43675064672775E-19"
          ixz="-9.55527713342861E-19"
          iyy="0.000116369867625823"
          iyz="-6.82730130760329E-06"
          izz="0.000534017963175619" />
      </inertial>
      <visual>
        <origin
          xyz="0 0 0"
          rpy="0 0 0" />
        <geometry>
          <mesh
            filename="package://rover_description/meshes/${tf_prefix}_left_upper_arm_link.STL" />
        </geometry>
        <material
          name="">
          <color
            rgba="1 0 0.501960784313725 1" />
        </material>
      </visual>
      <collision>
        <origin
          xyz="0 0 0"
          rpy="0 0 0" />
        <geometry>
          <mesh
            filename="package://rover_description/meshes/${tf_prefix}_left_upper_arm_link.STL" />
        </geometry>
      </collision>
    </link>
    <joint
      name="${tf_prefix}_left_upper_suspension_joint"
      type="continuous">
      <origin
        xyz="0 0.113030000000001 0.200078600000003"
        rpy="0 0 0" />
      <parent
        link="${tf_prefix}_base_link" />
      <child
        link="${tf_prefix}_left_upper_arm_link" />
      <axis
        xyz="${left_upper_suspension_x} 0 0" />
    </joint>
    <link
      name="${tf_prefix}_left_elbow_link">
      <inertial>
        <origin
          xyz="5.96744875736022E-16 0.0305089485053313 -0.0605771097242531"
          rpy="0 0 0" />
        <mass
          value="0.276177502867984" />
        <inertia
          ixx="0.00138370097439145"
          ixy="8.07765027386099E-19"
          ixz="9.09112644629632E-18"
          iyy="0.00118184162619849"
          iyz="1.67240900157383E-05"
          izz="0.000604637115743068" />
      </inertial>
      <visual>
        <origin
          xyz="0 0 0"
          rpy="0 0 0" />
        <geometry>
          <mesh
            filename="package://rover_description/meshes/${tf_prefix}_left_elbow_link.STL" />
        </geometry>
        <material
          name="">
          <color
            rgba="0.898039215686275 0.917647058823529 0.929411764705882 1" />
        </material>
      </visual>
      <collision>
        <origin
          xyz="0 0 0"
          rpy="0 0 0" />
        <geometry>
          <mesh
            filename="package://rover_description/meshes/${tf_prefix}_left_elbow_link.STL" />
        </geometry>
      </collision>
    </link>
    <joint
      name="${tf_prefix}_left_elbow_joint"
      type="continuous">
      <origin
        xyz="0 0.228006266355739 0.0164651906309959"
        rpy="0 0 0" />
      <parent
        link="${tf_prefix}_left_upper_arm_link" />
      <child
        link="${tf_prefix}_left_elbow_link" />
      <axis
        xyz="-1 0 0" />
      <mimic
        joint="${tf_prefix}_left_upper_suspension_joint"
        multiplier="${left_elbow_multiplier}"
        offset="0" />
    </joint>
    <link
      name="${tf_prefix}_left_steer_link">
      <inertial>
        <origin
          xyz="3.78475375387918E-05 0.0508607830999165 -0.034088886440541"
          rpy="0 0 0" />
        <mass
          value="0.405984022646422" />
        <inertia
          ixx="0.00172438585657843"
          ixy="-2.30866912288557E-08"
          ixz="6.62312988710791E-07"
          iyy="0.00196766144893258"
          iyz="0.000325354993938094"
          izz="0.00102637403801297" />
      </inertial>
      <visual>
        <origin
          xyz="0 0 0"
          rpy="0 0 0" />
        <geometry>
          <mesh
            filename="package://rover_description/meshes/${tf_prefix}_left_steer_link.STL" />
        </geometry>
        <material
          name="">
          <color
            rgba="0.792156862745098 0.819607843137255 0.933333333333333 1" />
        </material>
      </visual>
      <collision>
        <origin
          xyz="0 0 0"
          rpy="0 0 0" />
        <geometry>
          <mesh
            filename="package://rover_description/meshes/${tf_prefix}_left_steer_link.STL" />
        </geometry>
      </collision>
    </link>
    <joint
      name="${tf_prefix}_left_steer_joint"
      type="continuous">
      <origin
        xyz="0 0.0763524000002516 -0.142620999995403"
        rpy="0 0 0" />
      <parent
        link="${tf_prefix}_left_elbow_link" />
      <child
        link="${tf_prefix}_left_steer_link" />
      <axis
        xyz="0 0 1" />
    </joint>
    <link
      name="${tf_prefix}_left_drive_link">
      <inertial>
        <origin
          xyz="7.41530030434756E-09 -0.048581566054252 -4.98293268994393E-05"
          rpy="0 0 0" />
        <mass
          value="0.387386297168039" />
        <inertia
          ixx="0.000796364048811913"
          ixy="6.46596880540016E-18"
          ixz="-4.57089856939073E-19"
          iyy="0.000989327464865176"
          iyz="-3.36205821700588E-18"
          izz="0.000796364048811934" />
      </inertial>
      <visual>
        <origin
          xyz="0 0 0"
          rpy="0 0 0" />
        <geometry>
          <mesh
            filename="package://rover_description/meshes/${tf_prefix}_left_drive_link.STL" />
        </geometry>
        <material
          name="">
          <color
            rgba="0.792156862745098 0.819607843137255 0.933333333333333 1" />
        </material>
      </visual>
      <collision>
        <origin
          xyz="0 0 0"
          rpy="0 0 0" />
        <geometry>
          <mesh
            filename="package://rover_description/meshes/${tf_prefix}_left_drive_link.STL" />
        </geometry>
      </collision>
    </link>
    <joint
      name="${tf_prefix}_left_drive_joint"
      type="continuous">
      <origin
        xyz="0 0.17327879918155 -0.055067201398788"
        rpy="0 0 0" />
      <parent
        link="${tf_prefix}_left_steer_link" />
      <child
        link="${tf_prefix}_left_drive_link" />
      <axis
        xyz="0 1 0" />
    </joint>
    <link
      name="${tf_prefix}_left_lower_arm_link">
      <inertial>
        <origin
          xyz="-3.40005801291454E-16 0.0911912912348097 0.0093646541915277"
          rpy="0 0 0" />
        <mass
          value="0.0901506877798633" />
        <inertia
          ixx="0.00070994738946522"
          ixy="-1.21570038321086E-18"
          ixz="-4.46101311737314E-19"
          iyy="9.5968082032972E-05"
          iyz="-9.1705895885338E-05"
          izz="0.000719997616144062" />
      </inertial>
      <visual>
        <origin
          xyz="0 0 0"
          rpy="0 0 0" />
        <geometry>
          <mesh
            filename="package://rover_description/meshes/${tf_prefix}_left_lower_arm_link.STL" />
        </geometry>
        <material
          name="">
          <color
            rgba="0.341176470588235 0.83921568627451 0.411764705882353 1" />
        </material>
      </visual>
      <collision>
        <origin
          xyz="0 0 0"
          rpy="0 0 0" />
        <geometry>
          <mesh
            filename="package://rover_description/meshes/${tf_prefix}_left_lower_arm_link.STL" />
        </geometry>
      </collision>
    </link>
    <joint
      name="${tf_prefix}_left_lower_suspension_joint"
      type="continuous">
      <origin
        xyz="0 0.0685800000000013 0.111178600000029"
        rpy="0 0 0" />
      <parent
        link="${tf_prefix}_base_link" />
      <child
        link="${tf_prefix}_left_lower_arm_link" />
      <axis
        xyz="-1 0 0" />
      <mimic
        joint="${tf_prefix}_left_upper_suspension_joint"
        multiplier="${left_lower_suspension_multiplier}"
        offset="0" />
    </joint>
  </xacro:macro>

</robot>