<?xml version="1.0" encoding="utf-8"?>
<!-- This URDF was automatically created by SolidWorks to URDF Exporter! Originally created by Stephen Brawner (brawner@gmail.com) 
     Commit Version: 1.6.0-4-g7f85cfe  Build Version: 1.6.7995.38578
     For more information, please see http://wiki.ros.org/sw_urdf_exporter -->
<robot xmlns:xacro="http://wiki.ros.org/xacro">
  <xacro:macro name="rover_module" params="parent_link tf_prefix=''" >
    <link
      name="${tf_prefix}_base_link">
      <inertial>
        <origin
          xyz="6.73072708679001E-16 -1.16226472890446E-15 0.133292991245626"
          rpy="0 0 0" />
        <mass
          value="1.16420090238786" />
        <inertia
          ixx="0.0164887637751647"
          ixy="-1.90109720517605E-18"
          ixz="-2.6779793660392E-17"
          iyy="0.00758057045639268"
          iyz="-3.54663282927216E-18"
          izz="0.00955960807272672" />
      </inertial>
      <visual>
        <origin
          xyz="0 0 0"
          rpy="0 0 0" />
        <geometry>
          <mesh
            filename="package://rover_description/meshes/${tf_prefix}_base_link.STL" />
        </geometry>
        <material
          name="">
          <color
            rgba="0.898039215686275 0.917647058823529 0.929411764705882 1" />
        </material>
      </visual>
      <collision>
        <origin
          xyz="0 0 0"
          rpy="0 0 0" />
        <geometry>
          <mesh
            filename="package://REV_URDF/meshes/${tf_prefix}_base_link.STL" />
        </geometry>
      </collision>
    </link>
    <joint name="${tf_prefix}_base_joint" type="fixed">
        <parent link="${parent_link}"/>
        <child link="${tf_prefix}_base_link"/>
        <origin xyz="0 0 0" rpy="0 0 0"/>
    </joint>
    <link
      name="${tf_prefix}_right_upper_arm_link">
      <inertial>
        <origin
          xyz="4.5102810375397E-16 0.100934487761236 0.0100943196611427"
          rpy="0 0 0" />
        <mass
          value="0.0892451135572811" />
        <inertia
          ixx="0.00046676622139141"
          ixy="1.86279506342616E-19"
          ixz="4.78174344035076E-19"
          iyy="0.000121199569393539"
          iyz="4.51708066049292E-05"
          izz="0.000529188261407903" />
      </inertial>
      <visual>
        <origin
          xyz="0 0 0"
          rpy="0 0 0" />
        <geometry>
          <mesh
            filename="package://REV_URDF/meshes/${tf_prefix}_right_upper_arm_link.STL" />
        </geometry>
        <material
          name="">
          <color
            rgba="1 0 0.501960784313725 1" />
        </material>
      </visual>
      <collision>
        <origin
          xyz="0 0 0"
          rpy="0 0 0" />
        <geometry>
          <mesh
            filename="package://REV_URDF/meshes/${tf_prefix}_right_upper_arm_link.STL" />
        </geometry>
      </collision>
    </link>
    <joint
      name="${tf_prefix}_right_upper_suspension_joint"
      type="continuous">
      <origin
        xyz="0 0.113029999999999 0.200078600000003"
        rpy="0 0 0" />
      <parent
        link="${tf_prefix}_base_link" />
      <child
        link="${tf_prefix}_right_upper_arm_link" />
      <axis
        xyz="1 0 0" />
    </joint>
    <link
      name="${tf_prefix}_right_elbow_link">
      <inertial>
        <origin
          xyz="-5.55111512312578E-17 0.0305089499252609 -0.0605771152452138"
          rpy="0 0 0" />
        <mass
          value="0.276177502867985" />
        <inertia
          ixx="0.00138370097439145"
          ixy="3.65843055411021E-18"
          ixz="1.65982805902444E-18"
          iyy="0.00118184162619849"
          iyz="1.67240900157394E-05"
          izz="0.000604637115743067" />
      </inertial>
      <visual>
        <origin
          xyz="0 0 0"
          rpy="0 0 0" />
        <geometry>
          <mesh
            filename="package://REV_URDF/meshes/${tf_prefix}_right_elbow_link.STL" />
        </geometry>
        <material
          name="">
          <color
            rgba="0.898039215686275 0.917647058823529 0.929411764705882 1" />
        </material>
      </visual>
      <collision>
        <origin
          xyz="0 0 0"
          rpy="0 0 0" />
        <geometry>
          <mesh
            filename="package://REV_URDF/meshes/${tf_prefix}_right_elbow_link.STL" />
        </geometry>
      </collision>
    </link>
    <joint
      name="${tf_prefix}_right_elbow_joint"
      type="continuous">
      <origin
        xyz="0 0.228276454926942 -0.0121581300366316"
        rpy="0 0 0" />
      <parent
        link="${tf_prefix}_right_upper_arm_link" />
      <child
        link="${tf_prefix}_right_elbow_link" />
      <axis
        xyz="1 0 0" />
      <mimic
        joint="${tf_prefix}_right_upper_suspension_joint"
        multiplier="-1"
        offset="0" />
    </joint>
    <link
      name="${tf_prefix}_right_steer_link">
      <inertial>
        <origin
          xyz="4.00236261323406E-05 0.0556417912700981 -0.0380442098272852"
          rpy="0 0 0" />
        <mass
          value="0.491364303359802" />
        <inertia
          ixx="0.00176190750016323"
          ixy="-2.30868947654683E-08"
          ixz="5.99035081975555E-07"
          iyy="0.0021935871105742"
          iyz="0.00032535499113206"
          izz="0.00127549915002927" />
      </inertial>
      <visual>
        <origin
          xyz="0 0 0"
          rpy="0 0 0" />
        <geometry>
          <mesh
            filename="package://REV_URDF/meshes/${tf_prefix}_right_steer_link.STL" />
        </geometry>
        <material
          name="">
          <color
            rgba="0.792156862745098 0.819607843137255 0.933333333333333 1" />
        </material>
      </visual>
      <collision>
        <origin
          xyz="0 0 0"
          rpy="0 0 0" />
        <geometry>
          <mesh
            filename="package://REV_URDF/meshes/${tf_prefix}_right_steer_link.STL" />
        </geometry>
      </collision>
    </link>
    <joint
      name="${tf_prefix}_right_steer_joint"
      type="continuous">
      <origin
        xyz="0 0.0763523990440439 -0.142620999999999"
        rpy="0 0 0" />
      <parent
        link="${tf_prefix}_right_elbow_link" />
      <child
        link="${tf_prefix}_right_steer_link" />
      <axis
        xyz="0 0 -1" />
    </joint>
    <link
      name="${tf_prefix}_right_drive_link">
      <inertial>
        <origin
          xyz="-0.048581565295386 -5.56833923900935E-08 -4.95046406446265E-05"
          rpy="0 0 0" />
        <mass
          value="0.387386297168038" />
        <inertia
          ixx="0.000989327464865146"
          ixy="1.66221542882182E-18"
          ixz="-4.94423837917689E-19"
          iyy="0.000796364048811903"
          iyz="4.31986803099693E-19"
          izz="0.00079636404881191" />
      </inertial>
      <visual>
        <origin
          xyz="0 0 0"
          rpy="0 0 0" />
        <geometry>
          <mesh
            filename="package://REV_URDF/meshes/${tf_prefix}_right_drive_link.STL" />
        </geometry>
        <material
          name="">
          <color
            rgba="0.792156862745098 0.819607843137255 0.933333333333333 1" />
        </material>
      </visual>
      <collision>
        <origin
          xyz="0 0 0"
          rpy="0 0 0" />
        <geometry>
          <mesh
            filename="package://REV_URDF/meshes/${tf_prefix}_right_drive_link.STL" />
        </geometry>
      </collision>
    </link>
    <joint
      name="${tf_prefix}_right_drive_joint"
      type="continuous">
      <origin
        xyz="0 0.173278801303836 -0.05506722141481"
        rpy="0 0 1.5707963267949" />
      <parent
        link="${tf_prefix}_right_steer_link" />
      <child
        link="${tf_prefix}_right_drive_link" />
      <axis
        xyz="-1 0 0" />
    </joint>
    <link
      name="${tf_prefix}_right_lower_arm_link">
      <inertial>
        <origin
          xyz="7.0082828429463E-16 0.0916466970326932 -0.0021050577657087"
          rpy="0 0 0" />
        <mass
          value="0.0901506877798633" />
        <inertia
          ixx="0.000709947389465219"
          ixy="-6.43638617968201E-19"
          ixz="8.38601791901608E-21"
          iyy="8.29725501045178E-05"
          iyz="-1.14669854447379E-05"
          izz="0.000732993148072516" />
      </inertial>
      <visual>
        <origin
          xyz="0 0 0"
          rpy="0 0 0" />
        <geometry>
          <mesh
            filename="package://REV_URDF/meshes/${tf_prefix}_right_lower_arm_link.STL" />
        </geometry>
        <material
          name="">
          <color
            rgba="0.341176470588235 0.83921568627451 0.411764705882353 1" />
        </material>
      </visual>
      <collision>
        <origin
          xyz="0 0 0"
          rpy="0 0 0" />
        <geometry>
          <mesh
            filename="package://REV_URDF/meshes/${tf_prefix}_right_lower_arm_link.STL" />
        </geometry>
      </collision>
    </link>
    <joint
      name="${tf_prefix}_right_lower_suspension_joint"
      type="continuous">
      <origin
        xyz="0 0.0685799999999988 0.111178600000003"
        rpy="0 0 0" />
      <parent
        link="${tf_prefix}_base_link" />
      <child
        link="${tf_prefix}_right_lower_arm_link" />
      <axis
        xyz="-1 0 0" />
      <mimic
        joint="${tf_prefix}_right_upper_suspension_joint"
        multiplier="-1"
        offset="0" />
    </joint>
    <link
      name="${tf_prefix}_left_upper_arm_link">
      <inertial>
        <origin
          xyz="4.9960036108132E-16 -0.0988817033225721 0.0226290710607198"
          rpy="0 0 0" />
        <mass
          value="0.089245113557281" />
        <inertia
          ixx="0.00046676622139141"
          ixy="1.74809744189729E-19"
          ixz="6.43283406973188E-19"
          iyy="0.000116369863585223"
          iyz="6.82717771819935E-06"
          izz="0.000534017967216219" />
      </inertial>
      <visual>
        <origin
          xyz="0 0 0"
          rpy="0 0 0" />
        <geometry>
          <mesh
            filename="package://REV_URDF/meshes/${tf_prefix}_left_upper_arm_link.STL" />
        </geometry>
        <material
          name="">
          <color
            rgba="1 0 0.501960784313725 1" />
        </material>
      </visual>
      <collision>
        <origin
          xyz="0 0 0"
          rpy="0 0 0" />
        <geometry>
          <mesh
            filename="package://REV_URDF/meshes/${tf_prefix}_left_upper_arm_link.STL" />
        </geometry>
      </collision>
    </link>
    <joint
      name="${tf_prefix}_left_upper_suspension_joint"
      type="continuous">
      <origin
        xyz="0 -0.113030000000001 0.200078600000003"
        rpy="0 0 0" />
      <parent
        link="${tf_prefix}_base_link" />
      <child
        link="${tf_prefix}_left_upper_arm_link" />
      <axis
        xyz="1 0 0" />
    </joint>
    <link
      name="${tf_prefix}_left_elbow_link">
      <inertial>
        <origin
          xyz="-7.84095011141517E-16 -0.0305089494830144 -0.060577123263018"
          rpy="0 0 0" />
        <mass
          value="0.276177502867985" />
        <inertia
          ixx="0.00138370097439145"
          ixy="1.83842691405744E-18"
          ixz="-6.51992879210682E-18"
          iyy="0.00118184162619848"
          iyz="-1.67240900157389E-05"
          izz="0.000604637115743066" />
      </inertial>
      <visual>
        <origin
          xyz="0 0 0"
          rpy="0 0 0" />
        <geometry>
          <mesh
            filename="package://REV_URDF/meshes/${tf_prefix}_left_elbow_link.STL" />
        </geometry>
        <material
          name="">
          <color
            rgba="0.898039215686275 0.917647058823529 0.929411764705882 1" />
        </material>
      </visual>
      <collision>
        <origin
          xyz="0 0 0"
          rpy="0 0 0" />
        <geometry>
          <mesh
            filename="package://REV_URDF/meshes/${tf_prefix}_left_elbow_link.STL" />
        </geometry>
      </collision>
    </link>
    <joint
      name="${tf_prefix}_left_elbow_joint"
      type="continuous">
      <origin
        xyz="0 -0.228006270250389 0.0164651366987035"
        rpy="0 0 0" />
      <parent
        link="${tf_prefix}_left_upper_arm_link" />
      <child
        link="${tf_prefix}_left_elbow_link" />
      <axis
        xyz="1 0 0" />
      <mimic
        joint="${tf_prefix}_left_upper_suspension_joint"
        multiplier="-1"
        offset="0" />
    </joint>
    <link
      name="${tf_prefix}_left_steer_link">
      <inertial>
        <origin
          xyz="-3.78428625888508E-05 -0.0508607972379299 -0.0340889010328233"
          rpy="0 0 0" />
        <mass
          value="0.405984022646421" />
        <inertia
          ixx="0.00172438585657842"
          ixy="-2.30866912289839E-08"
          ixz="-6.62312988706773E-07"
          iyy="0.00196766144893258"
          iyz="-0.000325354993938091"
          izz="0.00102637403801297" />
      </inertial>
      <visual>
        <origin
          xyz="0 0 0"
          rpy="0 0 0" />
        <geometry>
          <mesh
            filename="package://REV_URDF/meshes/${tf_prefix}_left_steer_link.STL" />
        </geometry>
        <material
          name="">
          <color
            rgba="0.792156862745098 0.819607843137255 0.933333333333333 1" />
        </material>
      </visual>
      <collision>
        <origin
          xyz="0 0 0"
          rpy="0 0 0" />
        <geometry>
          <mesh
            filename="package://REV_URDF/meshes/${tf_prefix}_left_steer_link.STL" />
        </geometry>
      </collision>
    </link>
    <joint
      name="${tf_prefix}_left_steer_joint"
      type="continuous">
      <origin
        xyz="0 -0.076352399999746 -0.142620999999777"
        rpy="0 0 0" />
      <parent
        link="${tf_prefix}_left_elbow_link" />
      <child
        link="${tf_prefix}_left_steer_link" />
      <axis
        xyz="0 0 -1" />
    </joint>
    <link
      name="${tf_prefix}_left_drive_link">
      <inertial>
        <origin
          xyz="8.23120371723496E-08 0.0485815658289817 -4.98447529662244E-05"
          rpy="0 0 0" />
        <mass
          value="0.387386297168039" />
        <inertia
          ixx="0.000796364048811913"
          ixy="6.2393605215105E-18"
          ixz="-2.4006912400342E-18"
          iyy="0.000989327464865172"
          iyz="3.85702324714999E-18"
          izz="0.00079636404881193" />
      </inertial>
      <visual>
        <origin
          xyz="0 0 0"
          rpy="0 0 0" />
        <geometry>
          <mesh
            filename="package://REV_URDF/meshes/${tf_prefix}_left_drive_link.STL" />
        </geometry>
        <material
          name="">
          <color
            rgba="0.792156862745098 0.819607843137255 0.933333333333333 1" />
        </material>
      </visual>
      <collision>
        <origin
          xyz="0 0 0"
          rpy="0 0 0" />
        <geometry>
          <mesh
            filename="package://REV_URDF/meshes/${tf_prefix}_left_drive_link.STL" />
        </geometry>
      </collision>
    </link>
    <joint
      name="${tf_prefix}_left_drive_joint"
      type="continuous">
      <origin
        xyz="0 -0.173278800005411 -0.0550671999737736"
        rpy="0 0 0" />
      <parent
        link="${tf_prefix}_left_steer_link" />
      <child
        link="${tf_prefix}_left_drive_link" />
      <axis
        xyz="0 1 0" />
    </joint>
    <link
      name="${tf_prefix}_left_lower_arm_link">
      <inertial>
        <origin
          xyz="6.31439345255558E-16 -0.0911912940059711 0.00936462720642342"
          rpy="0 0 0" />
        <mass
          value="0.0901506877798632" />
        <inertia
          ixx="0.000709947389465219"
          ixy="5.41704316605017E-19"
          ixz="7.74517167313274E-20"
          iyy="9.59680277582578E-05"
          iyz="9.17057112240284E-05"
          izz="0.000719997670418776" />
      </inertial>
      <visual>
        <origin
          xyz="0 0 0"
          rpy="0 0 0" />
        <geometry>
          <mesh
            filename="package://REV_URDF/meshes/${tf_prefix}_left_lower_arm_link.STL" />
        </geometry>
        <material
          name="">
          <color
            rgba="0.341176470588235 0.83921568627451 0.411764705882353 1" />
        </material>
      </visual>
      <collision>
        <origin
          xyz="0 0 0"
          rpy="0 0 0" />
        <geometry>
          <mesh
            filename="package://REV_URDF/meshes/${tf_prefix}_left_lower_arm_link.STL" />
        </geometry>
      </collision>
    </link>
    <joint
      name="${tf_prefix}_left_lower_suspension_joint"
      type="continuous">
      <origin
        xyz="0 -0.0685800000000013 0.111178600000029"
        rpy="0 0 0" />
      <parent
        link="${tf_prefix}_base_link" />
      <child
        link="${tf_prefix}_left_lower_arm_link" />
      <axis
        xyz="1 0 0" />
      <mimic
        joint="${tf_prefix}_left_upper_suspension_joint"
        multiplier="1"
        offset="0" />
    </joint>
  </xacro:macro>
</robot>